Workbook

Sheet Overview
B2: Do Education and Health Move Together?
B3: Official-data build: correlation + a two-scorecard Progress Index (SDGs 3, 4, 7)
B5: Prepared by | D5: Joseph Wong: UC Berkeley, Data Science
B6: Program | D6: International Sibling Society (ISS), Summer 2026 Internship
B7: Deliverable | D7: Data Analytics Project, Phase 2 (Week 7)
B8: Data status | D8: OFFICIAL: pulled live from the UNSD SDG API + World Bank API on July 1, 2026
B9: Indicators | D9: Net primary enrollment (WB), under-5 mortality (UNSD), electricity access (UNSD)
B10: Countries / period | D10: Bangladesh, Ethiopia, Ghana, India, Nigeria, Rwanda; 2000-2023 yearly
B11: Pipeline | D11: pull_sdg_api_data.py (v1, this pull) and pull_sdg_api_data_v2.py (fixes, see API tab)
B12: Interactive dashboard | D12: interactive_dashboard.html (Python + Plotly): hover, zoom, indicator dropdown
B14: Research Question
B15: Do education and health outcomes move together across countries, and which countries lead once you score progress since 2000 instead of the level reached today?
B17: Phase 2 requirements covered (4 of 5)
B18: 1. SDG API | D18: Data pulled live from the UNSD SDG API and World Bank API in Python; pull executed July 1 (script + fix log on the API & Methods tab).
B19: 2. Two+ indicators | D19: Three indicators joined on country-year; correlation analysis on the Correlation tab.
B20: 3. Composite score | D20: Two min-max composite indices (level vs progress) with rankings on the Composite tab.
B21: 4. Interactive | D21: Plotly dashboard: hover any point, zoom, toggle countries, switch indicators (interactive_dashboard.html).
B22: (5. Forecasting) | D22: Covered by the Week 9 project, which projects the enrollment trend to 2030.
B24: Known gaps in this pull: maternal mortality (wrong series code in v1) and electricity is an all-areas average (urban/rural blended). Both are fixed in pull_sdg_api_data_v2.py; rerun it to complete the dataset. Details on the API & Methods tab.

Sheet Data
B2: Official yearly data: 6 countries x 24 years (144 rows)
B4: Country | C4: ISO | D4: Year | E4: Enroll % | F4: U5 mort | G4: Elec %
B5: Bangladesh | C5: BGD | D5: 2000 | F5: 85.45 | G5: 43.33
B6: Bangladesh | C6: BGD | D6: 2001 | F6: 80.14 | G6: 44.7
B7: Bangladesh | C7: BGD | D7: 2002 | F7: 75.25 | G7: 46.93
B8: Bangladesh | C8: BGD | D8: 2003 | F8: 70.78 | G8: 49.1
B9: Bangladesh | C9: BGD | D9: 2004 | F9: 66.7 | G9: 48.37
B10: Bangladesh | C10: BGD | D10: 2005 | E10: 93.69 | F10: 62.97 | G10: 52.33
B11: Bangladesh | C11: BGD | D11: 2006 | E11: 93.43 | F11: 59.54 | G11: 56.17
B12: Bangladesh | C12: BGD | D12: 2007 | F12: 56.43 | G12: 53.7
B13: Bangladesh | C13: BGD | D13: 2008 | E13: 92.57 | F13: 53.59 | G13: 60.4
B14: Bangladesh | C14: BGD | D14: 2009 | E14: 92.54 | F14: 51 | G14: 62.73
B15: Bangladesh | C15: BGD | D15: 2010 | E15: 90.53 | F15: 48.65 | G15: 61.8
B16: Bangladesh | C16: BGD | D16: 2011 | F16: 46.48 | G16: 65.17
B17: Bangladesh | C17: BGD | D17: 2012 | F17: 44.4 | G17: 69.97
B18: Bangladesh | C18: BGD | D18: 2013 | F18: 42.4 | G18: 66.03
B19: Bangladesh | C19: BGD | D19: 2014 | F19: 40.42 | G19: 67.07
B20: Bangladesh | C20: BGD | D20: 2015 | F20: 38.5 | G20: 77.13
B21: Bangladesh | C21: BGD | D21: 2016 | F21: 36.63 | G21: 78.67
B22: Bangladesh | C22: BGD | D22: 2017 | F22: 34.92 | G22: 89.7
B23: Bangladesh | C23: BGD | D23: 2018 | F23: 33.43 | G23: 88.27
B24: Bangladesh | C24: BGD | D24: 2019 | F24: 32.25 | G24: 92.97
B25: Bangladesh | C25: BGD | D25: 2020 | F25: 31.4 | G25: 96.4
B26: Bangladesh | C26: BGD | D26: 2021 | F26: 30.87 | G26: 99.07
B27: Bangladesh | C27: BGD | D27: 2022 | F27: 30.62 | G27: 99.57
B28: Bangladesh | C28: BGD | D28: 2023 | F28: 30.56 | G28: 99.53
B29: Ethiopia | C29: ETH | D29: 2000 | E29: 40.17 | F29: 139.93 | G29: 30.2
B30: Ethiopia | C30: ETH | D30: 2001 | E30: 43.94 | F30: 133.63 | G30: 44.75
B31: Ethiopia | C31: ETH | D31: 2002 | E31: 46.06 | F31: 127.26 | G31: 45.9
B32: Ethiopia | C32: ETH | D32: 2003 | E32: 46.78 | F32: 120.85 | G32: 31.83
B33: Ethiopia | C33: ETH | D33: 2004 | E33: 49.58 | F33: 114.4 | G33: 33.17
B34: Ethiopia | C34: ETH | D34: 2005 | E34: 60.39 | F34: 108.18 | G34: 33.43
B35: Ethiopia | C35: ETH | D35: 2006 | E35: 65.01 | F35: 102.26 | G35: 35.9
B36: Ethiopia | C36: ETH | D36: 2007 | E36: 70.07 | F36: 96.75 | G36: 37.27
B37: Ethiopia | C37: ETH | D37: 2008 | E37: 75.78 | F37: 91.65 | G37: 38.57
B38: Ethiopia | C38: ETH | D38: 2009 | E38: 75.36 | F38: 86.92 | G38: 39.93
B39: Ethiopia | C39: ETH | D39: 2010 | E39: 73.35 | F39: 82.54 | G39: 41.33
B40: Ethiopia | C40: ETH | D40: 2011 | E40: 77.23 | F40: 78.47 | G40: 39.27
B41: Ethiopia | C41: ETH | D41: 2012 | E41: 78.49 | F41: 74.64 | G41: 44.07
B42: Ethiopia | C42: ETH | D42: 2013 | F42: 71.02 | G42: 45.47
...

Sheet Correlation
B2: Do the indicators move together? (Pearson r on official yearly data)
B4: Indicator pair | C4: r | D4: Read
B5: Enrollment vs under-5 mortality | C5: =CORREL(Data!E5:E148,Data!F5:F148) -> -0.73045412 | D5: Strong negative across 62 paired country-years: more kids in school, fewer child deaths.
B6: Enrollment vs electricity access | C6: =CORREL(Data!E5:E148,Data!G5:G148) -> 0.53051535 | D6: Positive but moderate: development travels together, yet school can run ahead of power.
B7: Under-5 mortality vs electricity | C7: =CORREL(Data!F5:F148,Data!G5:G148) -> -0.57732185 | D7: Negative across all 144 rows: electrified places lose fewer children.
B9: Within single countries, enrollment vs under-5 mortality runs -0.94 to -0.98 for Ethiopia, Ghana, India, and Rwanda (the four with long observation windows). Two honest exceptions: Bangladesh shows +0.88 because its only observed window (2005-2010) is five years in which reported enrollment dipped while mortality kept falling, a small-window artifact rather than a real reversal. Nigeria shows roughly zero (+0.10) because its reported enrollment was flat from 2000 to 2010 and unreported since. Correlation is not causation either way: education, health, and electrification tend to improve together as systems develop.

Sheet Composite
B2: Two scorecards on official data: where you ARE vs how far you CAME
B4: Official facts per country (enrollment window as reported; under-5 full 2000-2023)
B5: Country | C5: E start | D5: yr | E5: E end | F5: yr | G5: pp/yr | H5: U5 2000 | I5: U5 2023 | J5: U5 red%
B6: Bangladesh | C6: =Data!E10 -> 93.69 | D6: =Data!D10 -> 2005 | E6: =Data!E15 -> 90.53 | F6: =Data!D15 -> 2010 | G6: =(E6-C6)/(F6-D6) -> -0.632 | H6: =Data!F5 -> 85.45 | I6: =Data!F28 -> 30.56 | J6: =(H6-I6)/H6 -> 0.64236396
B7: Ethiopia | C7: =Data!E29 -> 40.17 | D7: =Data!D29 -> 2000 | E7: =Data!E44 -> 84.62 | F7: =Data!D44 -> 2015 | G7: =(E7-C7)/(F7-D7) -> 2.9633333 | H7: =Data!F29 -> 139.93 | I7: =Data!F52 -> 51.4 | J7: =(H7-I7)/H7 -> 0.63267348
B8: Ghana | C8: =Data!E53 -> 62.48 | D8: =Data!D53 -> 2000 | E8: =Data!E72 -> 86.16 | F8: =Data!D72 -> 2019 | G8: =(E8-C8)/(F8-D8) -> 1.2463158 | H8: =Data!F53 -> 99.81 | I8: =Data!F76 -> 37.13 | J8: =(H8-I8)/H8 -> 0.62799319
B9: India | C9: =Data!E77 -> 79.51 | D9: =Data!D77 -> 2000 | E9: =Data!E90 -> 92.26 | F9: =Data!D90 -> 2013 | G9: =(E9-C9)/(F9-D9) -> 0.98076923 | H9: =Data!F77 -> 91.84 | I9: =Data!F100 -> 27.99 | J9: =(H9-I9)/H9 -> 0.69523084
B10: Nigeria | C10: =Data!E101 -> 65.09 | D10: =Data!D101 -> 2000 | E10: =Data!E111 -> 64.14 | F10: =Data!D111 -> 2010 | G10: =(E10-C10)/(F10-D10) -> -0.095 | H10: =Data!F101 -> 177.14 | I10: =Data!F124 -> 116.74 | J10: =(H10-I10)/H10 -> 0.34097324
B11: Rwanda | C11: =Data!E127 -> 81.18 | D11: =Data!D127 -> 2002 | E11: =Data!E143 -> 94.79 | F11: =Data!D143 -> 2018 | G11: =(E11-C11)/(F11-D11) -> 0.850625 | H11: =Data!F125 -> 184.03 | I11: =Data!F148 -> 38.73 | J11: =(H11-I11)/H11 -> 0.78954518
B13: Level Index: latest reported enrollment + 2023 under-5 (min-max, equal weights)
B14: Country | C14: E latest | D14: U5 2023 | E14: nE | F14: nU | G14: Index | H14: Rank
B15: Bangladesh | C15: =E6 -> 90.53 | D15: =I6 -> 30.56 | E15: =(C15-MIN($C$15:$C$20))/(MAX($C$15:$C$20)-MIN($C$15:$C$20)) -> 0.86101142 | F15: =(MAX($D$15:$D$20)-D15)/(MAX($D$15:$D$20)-MIN($D$15:$D$20)) -> 0.97104225 | G15: =AVERAGE(E15:F15) -> 0.91602684 | H15: =RANK(G15,$G$15:$G$20) -> 3
B16: Ethiopia | C16: =E7 -> 84.62 | D16: =I7 -> 51.4 | E16: =(C16-MIN($C$15:$C$20))/(MAX($C$15:$C$20)-MIN($C$15:$C$20)) -> 0.66818923 | F16: =(MAX($D$15:$D$20)-D16)/(MAX($D$15:$D$20)-MIN($D$15:$D$20)) -> 0.73622535 | G16: =AVERAGE(E16:F16) -> 0.70220729 | H16: =RANK(G16,$G$15:$G$20) -> 5
B17: Ghana | C17: =E8 -> 86.16 | D17: =I8 -> 37.13 | E17: =(C17-MIN($C$15:$C$20))/(MAX($C$15:$C$20)-MIN($C$15:$C$20)) -> 0.71843393 | F17: =(MAX($D$15:$D$20)-D17)/(MAX($D$15:$D$20)-MIN($D$15:$D$20)) -> 0.89701408 | G17: =AVERAGE(E17:F17) -> 0.80772401 | H17: =RANK(G17,$G$15:$G$20) -> 4
B18: India | C18: =E9 -> 92.26 | D18: =I9 -> 27.99 | E18: =(C18-MIN($C$15:$C$20))/(MAX($C$15:$C$20)-MIN($C$15:$C$20)) -> 0.91745514 | F18: =(MAX($D$15:$D$20)-D18)/(MAX($D$15:$D$20)-MIN($D$15:$D$20)) -> 1 | G18: =AVERAGE(E18:F18) -> 0.95872757 | H18: =RANK(G18,$G$15:$G$20) -> 1
B19: Nigeria | C19: =E10 -> 64.14 | D19: =I10 -> 116.74 | E19: =(C19-MIN($C$15:$C$20))/(MAX($C$15:$C$20)-MIN($C$15:$C$20)) -> 0 | F19: =(MAX($D$15:$D$20)-D19)/(MAX($D$15:$D$20)-MIN($D$15:$D$20)) -> 0 | G19: =AVERAGE(E19:F19) -> 0 | H19: =RANK(G19,$G$15:$G$20) -> 6
B20: Rwanda | C20: =E11 -> 94.79 | D20: =I11 -> 38.73 | E20: =(C20-MIN($C$15:$C$20))/(MAX($C$15:$C$20)-MIN($C$15:$C$20)) -> 1 | F20: =(MAX($D$15:$D$20)-D20)/(MAX($D$15:$D$20)-MIN($D$15:$D$20)) -> 0.87898592 | G20: =AVERAGE(E20:F20) -> 0.93949296 | H20: =RANK(G20,$G$15:$G$20) -> 2
B22: Progress Index: enrollment pp per year + under-5 % reduction (min-max, equal weights)
B23: Country | C23: pp/yr | D23: U5 red% | E23: nE | F23: nU | G23: Index | H23: Rank
B24: Bangladesh | C24: =G6 -> -0.632 | D24: =J6 -> 0.64236396 | E24: =(C24-MIN($C$24:$C$29))/(MAX($C$24:$C$29)-MIN($C$24:$C$29)) -> 0 | F24: =(D24-MIN($D$24:$D$29))/(MAX($D$24:$D$29)-MIN($D$24:$D$29)) -> 0.67188936 | G24: =AVERAGE(E24:F24) -> 0.33594468 | H24: =RANK(G24,$G$24:$G$29) -> 5
B25: Ethiopia | C25: =G7 -> 2.9633333 | D25: =J7 -> 0.63267348 | E25: =(C25-MIN($C$24:$C$29))/(MAX($C$24:$C$29)-MIN($C$24:$C$29)) -> 1 | F25: =(D25-MIN($D$24:$D$29))/(MAX($D$24:$D$29)-MIN($D$24:$D$29)) -> 0.65028641 | G25: =AVERAGE(E25:F25) -> 0.82514321 | H25: =RANK(G25,$G$24:$G$29) -> 1
B26: Ghana | C26: =G8 -> 1.2463158 | D26: =J8 -> 0.62799319 | E26: =(C26-MIN($C$24:$C$29))/(MAX($C$24:$C$29)-MIN($C$24:$C$29)) -> 0.52243161 | F26: =(D26-MIN($D$24:$D$29))/(MAX($D$24:$D$29)-MIN($D$24:$D$29)) -> 0.63985265 | G26: =AVERAGE(E26:F26) -> 0.58114213 | H26: =RANK(G26,$G$24:$G$29) -> 4
B27: India | C27: =G9 -> 0.98076923 | D27: =J9 -> 0.69523084 | E27: =(C27-MIN($C$24:$C$29))/(MAX($C$24:$C$29)-MIN($C$24:$C$29)) -> 0.44857294 | F27: =(D27-MIN($D$24:$D$29))/(MAX($D$24:$D$29)-MIN($D$24:$D$29)) -> 0.78974533 | G27: =AVERAGE(E27:F27) -> 0.61915913 | H27: =RANK(G27,$G$24:$G$29) -> 3
B28: Nigeria | C28: =G10 -> -0.095 | D28: =J10 -> 0.34097324 | E28: =(C28-MIN($C$24:$C$29))/(MAX($C$24:$C$29)-MIN($C$24:$C$29)) -> 0.14936028 | F28: =(D28-MIN($D$24:$D$29))/(MAX($D$24:$D$29)-MIN($D$24:$D$29)) -> 0 | G28: =AVERAGE(E28:F28) -> 0.074680141 | H28: =RANK(G28,$G$24:$G$29) -> 6
B29: Rwanda | C29: =G11 -> 0.850625 | D29: =J11 -> 0.78954518 | E29: =(C29-MIN($C$24:$C$29))/(MAX($C$24:$C$29)-MIN($C$24:$C$29)) -> 0.41237484 | F29: =(D29-MIN($D$24:$D$29))/(MAX($D$24:$D$29)-MIN($D$24:$D$29)) -> 1 | G29: =AVERAGE(E29:F29) -> 0.70618742 | H29: =RANK(G29,$G$24:$G$29) -> 2
B31: The rank flip on official data
B32: Country | C32: Level rank | D32: Progress rank | E32: Shift
B33: Bangladesh | C33: =H15 -> 3 | D33: =H24 -> 5 | E33: =C33-D33 -> -2
B34: Ethiopia | C34: =H16 -> 5 | D34: =H25 -> 1 | E34: =C34-D34 -> 4
B35: Ghana | C35: =H17 -> 4 | D35: =H26 -> 4 | E35: =C35-D35 -> 0
B36: India | C36: =H18 -> 1 | D36: =H27 -> 3 | E36: =C36-D36 -> -2
B37: Nigeria | C37: =H19 -> 6 | D37: =H28 -> 6 | E37: =C37-D37 -> 0
B38: Rwanda | C38: =H20 -> 2 | D38: =H29 -> 2 | E38: =C38-D38 -> 0
B40: Method notes: enrollment progress is annualized (pp per year) because reported windows differ by country (Bangladesh has only 2005-2010; Ghana has 2000-2019). Min-max normalization sets the best country to 1 and the worst to 0. This is the fully-official two-indicator version; maternal mortality and dimension-filtered electricity join after the v2 script rerun. With four indicators on representative data the same headline flip appeared.

Sheet Dashboard
B2: Phase 2 Dashboard (official data): the link, and the two scorecards
B3: 62 paired country-years, 2000-2019. Full interactive version: interactive_dashboard.html
B24: Chart 1 read: countries slide down-right as enrollment rises and child deaths fall. Blank enrollment years are real reporting gaps in the official sources.
B45: Chart 2 read: India leads on level but Ethiopia leads on progress (5th to 1st). Nigeria is last on both, the one clear intervention case.

Sheet API & Methods
B2: Data pipeline: what was pulled, what broke, what v2 fixes
B4: The pull actually happened
B5: This workbook runs on data pulled live from the UNSD SDG API and the World Bank API on July 1, 2026 using pull_sdg_api_data.py. The script makes paginated HTTP requests, parses the JSON, filters to six countries and 2000-2023, and merges everything on country and year into one CSV (144 rows).
B7: What came back clean
B8: Under-5 mortality (UNSD series SH_DYN_MORT) is complete: 24 years for all six countries, official UN IGME values. Net primary enrollment (World Bank SE.PRM.NENR) is official but sparse, which is genuine source sparsity, not a download problem: Nigeria stops reporting in 2010, India in 2013, Ethiopia in 2015, and Bangladesh has only 2005-2010. The gaps themselves are a finding: the countries most in need are often the least measured.
B10: What broke, and the fix (v2)
B11: Two bugs surfaced in v1. First, the maternal mortality series code SH_STA_MMR returned nothing; the correct UNSD code is SH_STA_MORT. Second, the UNSD electricity series reports urban, rural, and all-areas rows, and v1 averaged them together, inflating baselines for low-access countries (Rwanda 2000 shows 22.6 instead of about 6). pull_sdg_api_data_v2.py fixes both: corrected series code, a dimension filter that keeps only totals, and an auto-suggest that searches the live catalogue when a series returns empty. Rerunning v2 (about 2 minutes) completes the dataset; the electricity and correlation figures here will tighten slightly when it does.
B13: How the analysis handles the enrollment gaps
B14: Because reported windows differ by country, level comparisons use each country's latest reported value with the year labeled, and progress is annualized as percentage points per year over each country's own window. That keeps a 5-year window (Bangladesh) from being compared to a 19-year window (Ghana) as if they were the same.

Sheet Findings
B2: Findings & Analysis (official data)
B4: The question
B5: My first project showed education access climbing. My second showed child deaths falling. This one asks whether those are one story: do education and health move together, and which countries lead once you score progress since 2000 instead of the level reached today? This build runs on official data pulled live from the UN and World Bank APIs.
B7: The link holds on official data
B8: Across 62 paired country-year observations, enrollment and under-5 mortality correlate at r = -0.73. Inside the four countries with long reporting windows the link is much tighter: Ethiopia -0.98, Ghana -0.96, India -0.94, Rwanda -0.98. Where more kids are in school, fewer children die.
B10: Two honest exceptions worth naming
B11: Bangladesh shows a positive within-country correlation (+0.88), but its only reported window is five years (2005-2010) in which enrollment dipped a few points while mortality kept falling. That is a small-window artifact, not evidence that schooling hurts health. Nigeria shows roughly zero correlation because its reported enrollment was flat (65.1 to 64.1) from 2000 to 2010 and has not been reported since. Nigeria's education stall is real, and so is its measurement gap.
B13: Ethiopia is the story again
B14: Ethiopia's official enrollment climbed from 40.2 in 2000 to 84.6 by 2015, which is +2.96 percentage points per year, by far the fastest in the group. Rwanda cut under-5 mortality by 79 percent (184 down to 39), the biggest health gain. India cut child deaths by 69.5 percent while already sitting near the top on levels.
B16: The rank flip survives
B17: On the two fully-official indicators, the Level Index ranks India 1st, Rwanda 2nd, Bangladesh 3rd, Ghana 4th, Ethiopia 5th, Nigeria 6th. The Progress Index ranks Ethiopia 1st, Rwanda 2nd, India 3rd, Ghana 4th, Bangladesh 5th, Nigeria 6th. Ethiopia jumps four places the moment you measure distance traveled instead of position. Nigeria is last on both, which makes it the one clear case for targeted intervention rather than a better lens.
B19: Why this matters
... B26: On official UN and World Bank data: education and child survival rise together, the fastest movers are countries the off-track label writes off, and the one country failing on both scorecards is also the one that stopped reporting its education data. Progress is real, measurable, and hiding in plain sight.
